<?xml version="1.0" ?>
<!-- =================================================================================== -->
<!-- |    This document was autogenerated by xacro from lab03.main.xacro               | -->
<!-- |    EDITING THIS FILE BY HAND IS NOT RECOMMENDED                                 | -->
<!-- =================================================================================== -->
<robot name="lab03" xmlns:xacro="http://www.ros.org/wiki/xacro">
  <!--
         Properties for the robot bodies
    -->
  <material name="black">
    <color rgba="0.0 0.0 0.0 1.0"/>
  </material>
  <material name="blue">
    <color rgba="0.0 0.0 0.8 1.0"/>
  </material>
  <material name="green">
    <color rgba="0.0 0.8 0.0 1.0"/>
  </material>
  <material name="grey">
    <color rgba="0.2 0.2 0.2 1.0"/>
  </material>
  <material name="orange">
    <color rgba="1.0 0.423529411765 0.0392156862745 1.0"/>
  </material>
  <material name="brown">
    <color rgba="0.870588235294 0.811764705882 0.764705882353 1.0"/>
  </material>
  <material name="red">
    <color rgba="0.8 0.0 0.0 1.0"/>
  </material>
  <material name="white">
    <color rgba="1.0 1.0 1.0 1.0"/>
  </material>
  <link name="camera">
    <collision>
      <origin rpy="0 0 0" xyz="0 0 0"/>
      <geometry>
        <box size="0.05 0.05 0.05"/>
      </geometry>
    </collision>
    <visual>
      <origin rpy="0 0 0" xyz="0 0 0"/>
      <geometry>
        <box size="0.05 0.05 0.05"/>
      </geometry>
      <material name="black"/>
    </visual>
    <inertial>
      <mass value="1e-5"/>
      <origin rpy="0 0 0" xyz="0 0 0"/>
      <inertia ixx="1e-6" ixy="0" ixz="0" iyy="1e-6" iyz="0" izz="1e-6"/>
    </inertial>
  </link>
  <joint name="camera_joint" type="fixed">
    <!-- <axis xyz="0 1 0" /> -->
    <origin rpy="0 0 0" xyz="0 0 0.525"/>
    <parent link="robot_chassis"/>
    <child link="camera"/>
  </joint>
  <gazebo reference="robot_chassis">
    <material>Gazebo/DarkGray</material>
  </gazebo>
  <gazebo reference="left_wheel">
    <material>Gazebo/White</material>
  </gazebo>
  <gazebo reference="right_wheel">
    <material>Gazebo/White</material>
  </gazebo>
  <gazebo reference="front_glide">
    <material>Gazebo/Blue</material>
  </gazebo>
  <gazebo reference="rear_glide">
    <material>Gazebo/Blue</material>
  </gazebo>
  <gazebo reference="camera">
    <material>Gazebo/Red</material>
  </gazebo>
  <!-- Camera Plugin -->
  <gazebo reference="camera">
    <sensor name="camera1" type="camera">
      <update_rate>10</update_rate>
      <camera name="head">
        <horizontal_fov>1.3962634</horizontal_fov>
        <image>
          <width>640</width>
          <height>480</height>
          <format>R8G8B8</format>
        </image>
        <clip>
          <near>0.02</near>
          <far>300</far>
        </clip>
        <noise>
          <type>gaussian</type>
          <mean>0.0</mean>
          <stddev>0.007</stddev>
        </noise>
      </camera>
      <plugin filename="libgazebo_ros_camera.so" name="camera_controller">
        <alwaysOn>true</alwaysOn>
        <updateRate>0.0</updateRate>
        <cameraName>lab03/camera1</cameraName>
        <imageTopicName>image_raw</imageTopicName>
        <cameraInfoTopicName>camera_info</cameraInfoTopicName>
        <frameName>camera</frameName>
        <hackBaseline>0.07</hackBaseline>
        <distortionK1>0.0</distortionK1>
        <distortionK2>0.0</distortionK2>
        <distortionK3>0.0</distortionK3>
        <distortionT1>0.0</distortionT1>
        <distortionT2>0.0</distortionT2>
      </plugin>
    </sensor>
  </gazebo>
  <!-- TODO:
            parameterize elements below
     -->
  <gazebo>
    <plugin filename="libgazebo_ros_diff_drive.so" name="differential_drive_controller">
      <alwaysOn>true</alwaysOn>
      <updateRate>10</updateRate>
      <leftJoint>left_wheel_joint</leftJoint>
      <rightJoint>right_wheel_joint</rightJoint>
      <wheelSeparation>0</wheelSeparation>
      <wheelDiameter>1</wheelDiameter>
      <torque>20</torque>
      <commandTopic>cmd_vel</commandTopic>
      <odometryTopic>odom</odometryTopic>
      <odometryFrame>odom</odometryFrame>
      <robotBaseFrame>robot_chassis</robotBaseFrame>
    </plugin>
  </gazebo>
  <!-- Create a base link so that the robot can be away from the origin -->
  <link name="base_link"/>
  <!-- Create the robot chassis -->
  <link name="robot_chassis">
    <!-- Create the chassis visual -->
    <visual>
      <origin rpy="0 0 0" xyz="0 0 0"/>
      <geometry>
        <cylinder length="1" radius="1"/>
      </geometry>
      <material name="white"/>
    </visual>
    <!-- The wheel's collision shape -->
    <collision>
      <origin rpy="0 0 0" xyz="0 0 0"/>
      <geometry>
        <cylinder length="1" radius="1"/>
      </geometry>
    </collision>
    <inertial>
      <mass value="1570.79632679"/>
      <origin rpy="0 0 0" xyz="0 0 0"/>
      <inertia ixx="523.598775598" ixy="0" ixz="0" iyy="523.598775598" iyz="0" izz="785.398163397"/>
    </inertial>
  </link>
  <joint name="chassis_joint" type="fixed">
    <parent link="base_link"/>
    <child link="robot_chassis"/>
    <origin xyz="0 0 1.1"/>
  </joint>
  <!-- The wheel's rigid body -->
  <link name="left_wheel">
    <!-- Create the wheel visual -->
    <visual>
      <origin rpy="0 0 0" xyz="0 0 0"/>
      <geometry>
        <sphere radius="1"/>
      </geometry>
      <material name="red"/>
    </visual>
    <!-- The wheel's collision shape -->
    <collision>
      <origin rpy="0 0 0" xyz="0 0 0"/>
      <geometry>
        <sphere radius="1"/>
      </geometry>
    </collision>
    <inertial>
      <mass value="1256.63706144"/>
      <origin rpy="0 0 0" xyz="0 0 0"/>
      <inertia ixx="340.339204139" ixy="0" ixz="0" iyy="340.339204139" iyz="0" izz="628.318530718"/>
    </inertial>
  </link>
  <!-- Connect the wheel to its parent -->
  <joint name="left_wheel_joint" type="continuous">
    <parent link="robot_chassis"/>
    <child link="left_wheel"/>
    <origin rpy="0 0 0" xyz="0 -0.1 0"/>
    <axis xyz="0 1 0"/>
    <!-- <limit effort="10" velocity="10" /> -->
  </joint>
  <!-- The wheel's rigid body -->
  <link name="right_wheel">
    <!-- Create the wheel visual -->
    <visual>
      <origin rpy="0 0 0" xyz="0 0 0"/>
      <geometry>
        <sphere radius="1"/>
      </geometry>
      <material name="red"/>
    </visual>
    <!-- The wheel's collision shape -->
    <collision>
      <origin rpy="0 0 0" xyz="0 0 0"/>
      <geometry>
        <sphere radius="1"/>
      </geometry>
    </collision>
    <inertial>
      <mass value="1256.63706144"/>
      <origin rpy="0 0 0" xyz="0 0 0"/>
      <inertia ixx="340.339204139" ixy="0" ixz="0" iyy="340.339204139" iyz="0" izz="628.318530718"/>
    </inertial>
  </link>
  <!-- Connect the wheel to its parent -->
  <joint name="right_wheel_joint" type="continuous">
    <parent link="robot_chassis"/>
    <child link="right_wheel"/>
    <origin rpy="0 0 0" xyz="0 0.1 0"/>
    <axis xyz="0 1 0"/>
    <!-- <limit effort="10" velocity="10" /> -->
  </joint>
  <!-- The glide's rigid body -->
  <link name="front_glide">
    <!-- Create the glide visual -->
    <visual>
      <origin rpy="0 0 0" xyz="0 0 0"/>
      <geometry>
        <sphere radius="1"/>
      </geometry>
      <material name="blue"/>
    </visual>
    <!-- The glide's collision shape -->
    <collision>
      <origin rpy="0 0 0" xyz="0 0 0"/>
      <geometry>
        <sphere radius="1"/>
      </geometry>
    </collision>
    <inertial>
      <mass value="837.758040957"/>
      <inertia ixx="335.103216383" ixy="0" ixz="0" iyy="335.103216383" iyz="0" izz="335.103216383"/>
    </inertial>
  </link>
  <!-- Connect the glide to its parent -->
  <joint name="front_glide_joint" type="fixed">
    <parent link="robot_chassis"/>
    <child link="front_glide"/>
    <origin rpy="0 0 0" xyz="0 0 -0.5"/>
    <!-- <limit effort="10" velocity="10" /> -->
  </joint>
  <!-- The glide's rigid body -->
  <link name="rear_glide">
    <!-- Create the glide visual -->
    <visual>
      <origin rpy="0 0 0" xyz="0 0 0"/>
      <geometry>
        <sphere radius="1"/>
      </geometry>
      <material name="blue"/>
    </visual>
    <!-- The glide's collision shape -->
    <collision>
      <origin rpy="0 0 0" xyz="0 0 0"/>
      <geometry>
        <sphere radius="1"/>
      </geometry>
    </collision>
    <inertial>
      <mass value="837.758040957"/>
      <inertia ixx="335.103216383" ixy="0" ixz="0" iyy="335.103216383" iyz="0" izz="335.103216383"/>
    </inertial>
  </link>
  <!-- Connect the glide to its parent -->
  <joint name="rear_glide_joint" type="fixed">
    <parent link="robot_chassis"/>
    <child link="rear_glide"/>
    <origin rpy="0 0 0" xyz="0 0 -0.5"/>
    <!-- <limit effort="10" velocity="10" /> -->
  </joint>
</robot>

